{
    "project_name": "Math",
    "bug_id": "66",
    "test_id": 1,
    "ans": [
        {
            "method_id": 3,
            "reasoning": "The method getOptimaValues() throws an exception if no optimum has been computed yet. If this method is called after the optimization process without a successful computation of optima, it will lead to a failure in the test. The test expects valid optima values, making this method highly suspicious.",
            "rank": 1
        },
        {
            "method_id": 9,
            "reasoning": "The optimize() method is responsible for the optimization process. If there are issues in how it handles the function or the bounds, it could lead to incorrect optima being computed. This could indirectly cause the test to fail if the optimization does not yield valid results.",
            "rank": 2
        },
        {
            "method_id": 5,
            "reasoning": "The localMin() method contains the core logic for finding local minima. If there are logical errors in how it computes the objective value or handles the stopping criteria, it could lead to incorrect results. This method is complex and could be a source of subtle bugs.",
            "rank": 3
        },
        {
            "method_id": 4,
            "reasoning": "The getEvaluations() method simply returns the total number of evaluations. While it is less likely to be the source of the failure, if the evaluation count is not being tracked correctly, it could lead to issues in the optimization process. However, it is less suspicious compared to the others.",
            "rank": 4
        },
        {
            "method_id": 15,
            "reasoning": "The computeObjectiveValue() method is responsible for evaluating the function at a given point. If the function evaluation is incorrect, it could lead to wrong optimization results. However, since it is a utility function, it is less suspicious than the methods directly involved in the optimization process.",
            "rank": 5
        }
    ],
    "final_full_answer": "```json\n[\n    {\n        \"method_id\": 3,\n        \"reasoning\": \"The method getOptimaValues() throws an exception if no optimum has been computed yet. If this method is called after the optimization process without a successful computation of optima, it will lead to a failure in the test. The test expects valid optima values, making this method highly suspicious.\",\n        \"rank\": 1\n    },\n    {\n        \"method_id\": 9,\n        \"reasoning\": \"The optimize() method is responsible for the optimization process. If there are issues in how it handles the function or the bounds, it could lead to incorrect optima being computed. This could indirectly cause the test to fail if the optimization does not yield valid results.\",\n        \"rank\": 2\n    },\n    {\n        \"method_id\": 5,\n        \"reasoning\": \"The localMin() method contains the core logic for finding local minima. If there are logical errors in how it computes the objective value or handles the stopping criteria, it could lead to incorrect results. This method is complex and could be a source of subtle bugs.\",\n        \"rank\": 3\n    },\n    {\n        \"method_id\": 4,\n        \"reasoning\": \"The getEvaluations() method simply returns the total number of evaluations. While it is less likely to be the source of the failure, if the evaluation count is not being tracked correctly, it could lead to issues in the optimization process. However, it is less suspicious compared to the others.\",\n        \"rank\": 4\n    },\n    {\n        \"method_id\": 15,\n        \"reasoning\": \"The computeObjectiveValue() method is responsible for evaluating the function at a given point. If the function evaluation is incorrect, it could lead to wrong optimization results. However, since it is a utility function, it is less suspicious than the methods directly involved in the optimization process.\",\n        \"rank\": 5\n    }\n]\n```"
}