{
    "project_name": "Mockito",
    "bug_id": "21",
    "test_id": 0,
    "ans": [
        {
            "method_id": 46,
            "reasoning": "The method 'withOuterClass' attempts to create a new instance of a class using a constructor that requires an outer class instance. If the outer class instance is not of the correct type or if the target class does not have a parameter-less constructor, it will throw an exception. This aligns with the stack trace indicating an issue with creating a mock instance of 'SomeInnerClass'.",
            "rank": 1
        },
        {
            "method_id": 14,
            "reasoning": "The method 'newInstance' checks if the outer class instance is null and calls 'withOuterClass' if it is not. If the outer class instance is not set correctly, it could lead to the same issues seen in the stack trace. This method is directly involved in the instantiation process, making it suspicious.",
            "rank": 2
        },
        {
            "method_id": 35,
            "reasoning": "The constructor 'ConstructorInstantiator' initializes the outer class instance. If this instance is not set correctly or is of the wrong type, it could lead to issues in the instantiation methods. However, it is less directly related to the exception thrown in the test compared to methods 14 and 46.",
            "rank": 3
        },
        {
            "method_id": 41,
            "reasoning": "The method 'paramsException' is responsible for creating an exception message. While it is involved in the error handling process, it does not directly contribute to the instantiation logic that is failing. Therefore, it is the least suspicious method in this context.",
            "rank": 4
        }
    ],
    "final_full_answer": "```json\n[\n    {\n        \"method_id\": 46,\n        \"reasoning\": \"The method 'withOuterClass' attempts to create a new instance of a class using a constructor that requires an outer class instance. If the outer class instance is not of the correct type or if the target class does not have a parameter-less constructor, it will throw an exception. This aligns with the stack trace indicating an issue with creating a mock instance of 'SomeInnerClass'.\",\n        \"rank\": 1\n    },\n    {\n        \"method_id\": 14,\n        \"reasoning\": \"The method 'newInstance' checks if the outer class instance is null and calls 'withOuterClass' if it is not. If the outer class instance is not set correctly, it could lead to the same issues seen in the stack trace. This method is directly involved in the instantiation process, making it suspicious.\",\n        \"rank\": 2\n    },\n    {\n        \"method_id\": 35,\n        \"reasoning\": \"The constructor 'ConstructorInstantiator' initializes the outer class instance. If this instance is not set correctly or is of the wrong type, it could lead to issues in the instantiation methods. However, it is less directly related to the exception thrown in the test compared to methods 14 and 46.\",\n        \"rank\": 3\n    },\n    {\n        \"method_id\": 41,\n        \"reasoning\": \"The method 'paramsException' is responsible for creating an exception message. While it is involved in the error handling process, it does not directly contribute to the instantiation logic that is failing. Therefore, it is the least suspicious method in this context.\",\n        \"rank\": 4\n    }\n]\n```"
}